<?xml version="1.0"?>
<robot name="my_bot" xmlns:xacro="http://www.ros.org/wiki/xacro">

	<material name="white">
		<color rgba="1 1 1 1"/>
	</material>
	<material name="black">
		<color rgba="0 0 0 1"/>
	</material>
	<material name="green">
		<color rgba="0 1 0 1"/>
	</material>
	<material name="blue">
		<color rgba="0 0 1 1"/>
	</material>

	<link name="base_link">
		<visual>
			<material name="white"/>
			<geometry>
				<box size="0.3 0.3 0.18"/>
			</geometry>
		</visual>
		<collision>
			<geometry>
				<box size="0.3 0.3 0.18"/>
			</geometry>
		</collision>
		<inertial>
			<mass value="6"/>
			<inertia ixx="0.05625" ixy="0.0" ixz="0.0" 						 iyy="0.05625" iyz="0.0" izz="0.05625"/>
		</inertial>
	</link>

    <xacro:macro name="wheel" params="prefix1 prefix2 reflect1 reflect2">
		<link name="${prefix1}_${prefix2}_wheel">
			<visual>
				<material name="black"/>
				<origin rpy="1.57075 0 0" xyz="0 0 0"/>
				<geometry>
					<cylinder length="0.05" radius="0.05"/>
				</geometry>
			</visual>
			<collision>
				<origin rpy="1.57075 0 0" xyz="0 0 0"/>
				<geometry>
					<cylinder length="0.05" radius="0.0375"/>
				</geometry>
			</collision>
			<inertial>
				<mass value="0.6"/>
				<inertia ixx="0.0005" ixy="0.0" ixz="0.0" 						 iyy="0.0005" iyz="0.0" izz="0.0005"/>
			</inertial>
		</link>
	
		<joint name="${prefix1}_${prefix2}_wheel_joint" type="continuous">
			<axis rpy="0 0 0" xyz="0 1 0"/>
			<parent link="base_link"/>
			<child link="${prefix1}_${prefix2}_wheel"/>
			<origin rpy="0 0 0" xyz="${reflect1*0.0875} ${reflect2*0.185} -0.07"/>
		</joint>
    </xacro:macro>

    <xacro:wheel prefix1="front" prefix2="right" reflect1="1" reflect2="1"/>
    <xacro:wheel prefix1="front" prefix2="left" reflect1="1" reflect2="-1"/>
    <xacro:wheel prefix1="rear" prefix2="right" reflect1="-1" reflect2="1"/>
    <xacro:wheel prefix1="rear" prefix2="left" reflect1="-1" reflect2="-1"/>

	<link name="gripper_pole">
		<visual>
			<geometry>
    	    <cylinder length="0.26" radius="0.01"/>
			</geometry>
			<origin rpy="0 1.57075 0 " xyz="0 0 0"/>
	    </visual>
	</link>	

	<joint name="gripper_extension" type="prismatic">
	    <parent link="base_link"/>
		<child link="gripper_pole"/>
	    <limit effort="1000.0" lower="0.03" upper="0.13" velocity="0.5"/>
	    <origin rpy="0 0 0" xyz="0 0 0.10"/>
	</joint>

	<xacro:macro name="gripper" params="prefix reflect">
		<link name="${prefix}_gripper">
			<visual>
				<origin rpy="${(reflect-1)*-1.57075} 0 0" xyz="0 0 0"/>
				<geometry>
        		<mesh filename="package://urdf_tutorial/meshes/l_finger.dae"/>
      			</geometry>
    		</visual>
  		</link>

		<joint name="${prefix}_gripper_joint" type="revolute">
   			<axis xyz="0 0 ${reflect*1}"/>
    		<limit effort="1000.0" lower="0.0" upper="0.548" velocity="0.5"/>
    		<origin rpy="0 0 0" xyz="0.13 ${reflect*1/100} 0"/>
    		<parent link="gripper_pole"/>
    		<child link="${prefix}_gripper"/>
  		</joint>

		<link name="${prefix}_tip">
		    <visual>
			    <origin rpy="${(reflect-1)*1.57075} 0 0" xyz="0.09137 ${(reflect)*0.00495} 0"/>
      			<geometry>
        		<mesh filename="package://urdf_tutorial/meshes/l_finger_tip.dae"/>
      			</geometry>
    		</visual>
  		</link>

		<joint name="${prefix}_tip_joint" type="fixed">
    		<parent link="${prefix}_gripper"/>
    		<child link="${prefix}_tip"/>
  		</joint>

	</xacro:macro>  

	<xacro:gripper prefix="left" reflect="1"/>
	<xacro:gripper prefix="right" reflect="-1"/>
</robot>

